Workbook

Sheet Summary
A1: Montana deer harvest, statewide
A2: Totals are formulas over the Data sheet, so they update if you edit it.
A4: Year | B4: Mule deer | C4: Whitetail | D4: All deer | E4: Change vs prior year
A5: 2021 | B5: =SUMIFS(Data!$G$2:$G$1409,Data!$C$2:$C$1409,"mule deer",Data!$D$2:$D$1409,A5) | C5: =SUMIFS(Data!$G$2:$G$1409,Data!$C$2:$C$1409,"whitetail",Data!$D$2:$D$1409,A5) | D5: =B5+C5 | E5: –
A6: 2022 | B6: =SUMIFS(Data!$G$2:$G$1409,Data!$C$2:$C$1409,"mule deer",Data!$D$2:$D$1409,A6) | C6: =SUMIFS(Data!$G$2:$G$1409,Data!$C$2:$C$1409,"whitetail",Data!$D$2:$D$1409,A6) | D6: =B6+C6 | E6: =IF(D5>0,D6/D5-1,"")
A7: 2023 | B7: =SUMIFS(Data!$G$2:$G$1409,Data!$C$2:$C$1409,"mule deer",Data!$D$2:$D$1409,A7) | C7: =SUMIFS(Data!$G$2:$G$1409,Data!$C$2:$C$1409,"whitetail",Data!$D$2:$D$1409,A7) | D7: =B7+C7 | E7: =IF(D6>0,D7/D6-1,"")
A8: 2024 | B8: =SUMIFS(Data!$G$2:$G$1409,Data!$C$2:$C$1409,"mule deer",Data!$D$2:$D$1409,A8) | C8: =SUMIFS(Data!$G$2:$G$1409,Data!$C$2:$C$1409,"whitetail",Data!$D$2:$D$1409,A8) | D8: =B8+C8 | E8: =IF(D7>0,D8/D7-1,"")
A9: 2025 | B9: =SUMIFS(Data!$G$2:$G$1409,Data!$C$2:$C$1409,"mule deer",Data!$D$2:$D$1409,A9) | C9: =SUMIFS(Data!$G$2:$G$1409,Data!$C$2:$C$1409,"whitetail",Data!$D$2:$D$1409,A9) | D9: =B9+C9 | E9: =IF(D8>0,D9/D8-1,"")
A11: Source: Montana FWP harvest estimates (myfwp.mt.gov). FWP counts deer hunters per district, not per species. Some years (e.g. 2022, 2024) have no hunter survey.

Sheet Top Districts
A1: Best-odds districts, 2025
A2: Ranked by harvest per deer hunter, districts with 100+ hunters. 2025 is the latest year FWP surveyed hunter numbers.
A4: Mule Deer | H4: Whitetail
A5: # | B5: District | C5: Hunters | D5: Harvest | E5: Per hunter | F5: Days per animal | H5: # | I5: District | J5: Hunters | K5: Harvest | L5: Per hunter | M5: Days per animal
A6: 1 | B6: 392 | C6: 691 | D6: 327 | E6: =D6/C6 | F6: 15.550459 | H6: 1 | I6: 170 | J6: 2713 | K6: 1750 | L6: =K6/J6 | M6: 11.163429
A7: 2 | B7: 405 | C7: 1279 | D7: 588 | E7: =D7/C7 | F7: 10.739796 | H7: 2 | I7: 444 | J7: 840 | K7: 491 | L7: =K7/J7 | M7: 11.647658
A8: 3 | B8: 471 | C8: 640 | D8: 284 | E8: =D8/C8 | F8: 18.65493 | H8: 3 | I8: 260 | J8: 1130 | K8: 633 | L8: =K8/J8 | M8: 14.481833
A9: 4 | B9: 640 | C9: 2776 | D9: 1225 | E9: =D9/C9 | F9: 14.009796 | H9: 4 | I9: 445 | J9: 1281 | K9: 658 | L9: =K9/J9 | M9: 9.9711246
A10: 5 | B10: 403 | C10: 418 | D10: 183 | E10: =D10/C10 | F10: 11.743169 | H10: 5 | I10: 309 | J10: 802 | K10: 346 | L10: =K10/J10 | M10: 15.575145
A11: 6 | B11: 652 | C11: 123 | D11: 52 | E11: =D11/C11 | F11: 14.115385 | H11: 6 | I11: 262 | J11: 804 | K11: 327 | L11: =K11/J11 | M11: 15.993884
A12: 7 | B12: 650 | C12: 2010 | D12: 843 | E12: =D12/C12 | F12: 14.570581 | H12: 7 | I12: 311 | J12: 1633 | K12: 653 | L12: =K12/J12 | M12: 14.48392
A13: 8 | B13: 704 | C13: 4306 | D13: 1770 | E13: =D13/C13 | F13: 14.468362 | H13: 8 | I13: 121 | J13: 2639 | K13: 979 | L13: =K13/J13 | M13: 23.47906
A14: 9 | B14: 690 | C14: 2914 | D14: 1194 | E14: =D14/C14 | F14: 13.00335 | H14: 9 | I14: 100 | J14: 2765 | K14: 1021 | L14: =K14/J14 | M14: 22.073457
A15: 10 | B15: 705 | C15: 3585 | D15: 1463 | E15: =D15/C15 | F15: 14.129187 | H15: 10 | I15: 101 | J15: 2913 | K15: 1066 | L15: =K15/J15 | M15: 20.655722
A16: 11 | B16: 426 | C16: 835 | D16: 335 | E16: =D16/C16 | F16: 12.946269 | H16: 11 | I16: 261 | J16: 486 | K16: 174 | L16: =K16/J16 | M16: 16.965517
A17: 12 | B17: 502 | C17: 1625 | D17: 650 | E17: =D17/C17 | F17: 12.815385 | H17: 12 | I17: 580 | J17: 1399 | K17: 496 | L17: =K17/J17 | M17: 15.705645
... A30: 25 | B30: 700 | C30: 3259 | D30: 1015 | E30: =D30/C30 | F30: 23.431527 | H30: 25 | I30: 104 | J30: 1575 | K30: 469 | L30: =K30/J30 | M30: 27.462687

Sheet Trends
A1: Harvest by district and year
A2: Darker green = more animals taken (shaded per species). Change compares the first and latest year.
A4: Mule Deer
A5: District | B5: Region | C5: 2021 | D5: 2022 | E5: 2023 | F5: 2024 | G5: 2025 | H5: Change
A6: 100 | B6: 1 | C6: 165 | D6: 176 | E6: 169 | F6: 113 | G6: 119 | H6: =IF(AND(ISNUMBER(C6),C6>0,ISNUMBER(G6)),G6/C6-1,"")
A7: 101 | B7: 1 | C7: 74 | D7: 110 | E7: 106 | F7: 125 | G7: 92 | H7: =IF(AND(ISNUMBER(C7),C7>0,ISNUMBER(G7)),G7/C7-1,"")
A8: 102 | B8: 1 | C8: 54 | H8: =IF(AND(ISNUMBER(C8),C8>0,ISNUMBER(G8)),G8/C8-1,"")
A9: 103 | B9: 1 | C9: 138 | D9: 158 | E9: 207 | F9: 233 | G9: 212 | H9: =IF(AND(ISNUMBER(C9),C9>0,ISNUMBER(G9)),G9/C9-1,"")
A10: 104 | B10: 1 | C10: 57 | D10: 39 | E10: 59 | F10: 66 | G10: 64 | H10: =IF(AND(ISNUMBER(C10),C10>0,ISNUMBER(G10)),G10/C10-1,"")
A11: 109 | B11: 1 | C11: 39 | H11: =IF(AND(ISNUMBER(C11),C11>0,ISNUMBER(G11)),G11/C11-1,"")
A12: 110 | B12: 1 | C12: 8 | D12: 20 | E12: 40 | F12: 25 | G12: 38 | H12: =IF(AND(ISNUMBER(C12),C12>0,ISNUMBER(G12)),G12/C12-1,"")
A13: 120 | B13: 1 | C13: 36 | D13: 49 | E13: 47 | F13: 34 | G13: 52 | H13: =IF(AND(ISNUMBER(C13),C13>0,ISNUMBER(G13)),G13/C13-1,"")
A14: 121 | B14: 1 | C14: 130 | D14: 120 | E14: 131 | F14: 169 | G14: 176 | H14: =IF(AND(ISNUMBER(C14),C14>0,ISNUMBER(G14)),G14/C14-1,"")
A15: 122 | B15: 1 | C15: 123 | D15: 158 | E15: 189 | F15: 201 | G15: 160 | H15: =IF(AND(ISNUMBER(C15),C15>0,ISNUMBER(G15)),G15/C15-1,"")
A16: 123 | B16: 1 | C16: 19 | D16: 26 | E16: 47 | F16: 72 | G16: 53 | H16: =IF(AND(ISNUMBER(C16),C16>0,ISNUMBER(G16)),G16/C16-1,"")
A17: 124 | B17: 1 | C17: 27 | D17: 71 | E17: 65 | F17: 53 | G17: 75 | H17: =IF(AND(ISNUMBER(C17),C17>0,ISNUMBER(G17)),G17/C17-1,"")
A18: 130 | B18: 1 | C18: 14 | D18: 33 | E18: 20 | F18: 32 | G18: 45 | H18: =IF(AND(ISNUMBER(C18),C18>0,ISNUMBER(G18)),G18/C18-1,"")
A19: 140 | B19: 1 | C19: 28 | D19: 36 | E19: 44 | F19: 31 | G19: 33 | H19: =IF(AND(ISNUMBER(C19),C19>0,ISNUMBER(G19)),G19/C19-1,"")
A20: 141 | B20: 1 | C20: 11 | D20: 7 | E20: 10 | F20: 3 | G20: 7 | H20: =IF(AND(ISNUMBER(C20),C20>0,ISNUMBER(G20)),G20/C20-1,"")
A21: 150 | B21: 1 | C21: 8 | D21: 10 | E21: 9 | F21: 12 | G21: 10 | H21: =IF(AND(ISNUMBER(C21),C21>0,ISNUMBER(G21)),G21/C21-1,"")
A22: 170 | B22: 1 | C22: 48 | D22: 40 | E22: 44 | F22: 36 | G22: 22 | H22: =IF(AND(ISNUMBER(C22),C22>0,ISNUMBER(G22)),G22/C22-1,"")
A23: 200 | B23: 2 | C23: 23 | D23: 10 | E23: 45 | F23: 34 | G23: 28 | H23: =IF(AND(ISNUMBER(C23),C23>0,ISNUMBER(G23)),G23/C23-1,"")
... A25: 202 | B25: 2 | C25: 95 | D25: 67 | E25: 83 | F25: 99 | G25: 104 | H25: =IF(AND(ISNUMBER(C25),C25>0,ISNUMBER(G25)),G25/C25-1,"")
A26: 203 | B26: 2 | C26: 96 | H26: =IF(AND(ISNUMBER(C26),C26>0,ISNUMBER(G26)),G26/C26-1,"")
A27: 204 | B27: 2 | C27: 72 | D27: 95 | E27: 138 | F27: 67 | G27: 92 | H27: =IF(AND(ISNUMBER(C27),C27>0,ISNUMBER(G27)),G27/C27-1,"")
A28: 210 | B28: 2 | C28: 49 | D28: 57 | E28: 67 | F28: 74 | G28: 62 | H28: =IF(AND(ISNUMBER(C28),C28>0,ISNUMBER(G28)),G28/C28-1,"")
A29: 211 | B29: 2 | C29: 35 | D29: 31 | E29: 40 | F29: 53 | G29: 37 | H29: =IF(AND(ISNUMBER(C29),C29>0,ISNUMBER(G29)),G29/C29-1,"")
A30: 212 | B30: 2 | C30: 38 | D30: 49 | E30: 43 | F30: 62 | G30: 79 | H30: =IF(AND(ISNUMBER(C30),C30>0,ISNUMBER(G30)),G30/C30-1,"")
A31: 213 | B31: 2 | C31: 104 | D31: 129 | E31: 145 | F31: 180 | G31: 199 | H31: =IF(AND(ISNUMBER(C31),C31>0,ISNUMBER(G31)),G31/C31-1,"")
A32: 214 | B32: 2 | C32: 16 | D32: 20 | E32: 27 | F32: 45 | G32: 14 | H32: =IF(AND(ISNUMBER(C32),C32>0,ISNUMBER(G32)),G32/C32-1,"")
A33: 215 | B33: 2 | C33: 86 | D33: 150 | E33: 140 | F33: 188 | G33: 161 | H33: =IF(AND(ISNUMBER(C33),C33>0,ISNUMBER(G33)),G33/C33-1,"")
A34: 216 | B34: 2 | C34: 55 | D34: 74 | E34: 72 | F34: 75 | G34: 90 | H34: =IF(AND(ISNUMBER(C34),C34>0,ISNUMBER(G34)),G34/C34-1,"")
A35: 217 | B35: 2 | C35: 44 | D35: 40 | E35: 32 | F35: 44 | G35: 52 | H35: =IF(AND(ISNUMBER(C35),C35>0,ISNUMBER(G35)),G35/C35-1,"")
A36: 240 | B36: 2 | C36: 114 | D36: 108 | E36: 114 | F36: 132 | G36: 135 | H36: =IF(AND(ISNUMBER(C36),C36>0,ISNUMBER(G36)),G36/C36-1,"")
A37: 250 | B37: 2 | C37: 17 | D37: 22 | E37: 23 | F37: 17 | G37: 18 | H37: =IF(AND(ISNUMBER(C37),C37>0,ISNUMBER(G37)),G37/C37-1,"")
A38: 260 | B38: 2 | C38: 33 | D38: 42 | E38: 45 | F38: 6 | G38: 35 | H38: =IF(AND(ISNUMBER(C38),C38>0,ISNUMBER(G38)),G38/C38-1,"")
... A44: 282 | B44: 2 | C44: 8 | D44: 17 | E44: 5 | F44: 11 | G44: 11 | H44: =IF(AND(ISNUMBER(C44),C44>0,ISNUMBER(G44)),G44/C44-1,"")
A45: 283 | B45: 2 | C45: 35 | H45: =IF(AND(ISNUMBER(C45),C45>0,ISNUMBER(G45)),G45/C45-1,"")
A46: 284 | B46: 2 | C46: 3 | D46: 10 | E46: 7 | F46: 3 | G46: 13 | H46: =IF(AND(ISNUMBER(C46),C46>0,ISNUMBER(G46)),G46/C46-1,"")
A47: 285 | B47: 2 | C47: 44 | D47: 85 | E47: 100 | F47: 109 | G47: 144 | H47: =IF(AND(ISNUMBER(C47),C47>0,ISNUMBER(G47)),G47/C47-1,"")
...

Sheet Data
A1: District | B1: Region | C1: Species | D1: Year | E1: Hunters | F1: Hunter days | G1: Harvest | H1: Per hunter | I1: Days per animal
A2: 100 | B2: 1 | C2: mule deer | D2: 2021 | E2: 2402 | F2: 17422 | G2: 165 | H2: =IF(E2>0,G2/E2,"") | I2: =IF(AND(F2>0,G2>0),F2/G2,"")
A3: 100 | B3: 1 | C3: mule deer | D3: 2022 | G3: 176 | H3: =IF(E3>0,G3/E3,"") | I3: =IF(AND(F3>0,G3>0),F3/G3,"")
A4: 100 | B4: 1 | C4: mule deer | D4: 2023 | E4: 2846 | F4: 23556 | G4: 169 | H4: =IF(E4>0,G4/E4,"") | I4: =IF(AND(F4>0,G4>0),F4/G4,"")
A5: 100 | B5: 1 | C5: mule deer | D5: 2024 | G5: 113 | H5: =IF(E5>0,G5/E5,"") | I5: =IF(AND(F5>0,G5>0),F5/G5,"")
A6: 100 | B6: 1 | C6: mule deer | D6: 2025 | E6: 2765 | F6: 22537 | G6: 119 | H6: =IF(E6>0,G6/E6,"") | I6: =IF(AND(F6>0,G6>0),F6/G6,"")
A7: 101 | B7: 1 | C7: mule deer | D7: 2021 | E7: 2328 | F7: 15644 | G7: 74 | H7: =IF(E7>0,G7/E7,"") | I7: =IF(AND(F7>0,G7>0),F7/G7,"")
A8: 101 | B8: 1 | C8: mule deer | D8: 2022 | G8: 110 | H8: =IF(E8>0,G8/E8,"") | I8: =IF(AND(F8>0,G8>0),F8/G8,"")
A9: 101 | B9: 1 | C9: mule deer | D9: 2023 | E9: 2955 | F9: 21834 | G9: 106 | H9: =IF(E9>0,G9/E9,"") | I9: =IF(AND(F9>0,G9>0),F9/G9,"")
A10: 101 | B10: 1 | C10: mule deer | D10: 2024 | G10: 125 | H10: =IF(E10>0,G10/E10,"") | I10: =IF(AND(F10>0,G10>0),F10/G10,"")
A11: 101 | B11: 1 | C11: mule deer | D11: 2025 | E11: 2913 | F11: 22019 | G11: 92 | H11: =IF(E11>0,G11/E11,"") | I11: =IF(AND(F11>0,G11>0),F11/G11,"")
A12: 102 | B12: 1 | C12: mule deer | D12: 2021 | E12: 2620 | F12: 15805 | G12: 54 | H12: =IF(E12>0,G12/E12,"") | I12: =IF(AND(F12>0,G12>0),F12/G12,"")
A13: 103 | B13: 1 | C13: mule deer | D13: 2021 | E13: 2546 | F13: 18236 | G13: 138 | H13: =IF(E13>0,G13/E13,"") | I13: =IF(AND(F13>0,G13>0),F13/G13,"")
A14: 103 | B14: 1 | C14: mule deer | D14: 2022 | G14: 158 | H14: =IF(E14>0,G14/E14,"") | I14: =IF(AND(F14>0,G14>0),F14/G14,"")
A15: 103 | B15: 1 | C15: mule deer | D15: 2023 | E15: 5391 | F15: 39826 | G15: 207 | H15: =IF(E15>0,G15/E15,"") | I15: =IF(AND(F15>0,G15>0),F15/G15,"")
A16: 103 | B16: 1 | C16: mule deer | D16: 2024 | G16: 233 | H16: =IF(E16>0,G16/E16,"") | I16: =IF(AND(F16>0,G16>0),F16/G16,"")
A17: 103 | B17: 1 | C17: mule deer | D17: 2025 | E17: 5147 | F17: 35014 | G17: 212 | H17: =IF(E17>0,G17/E17,"") | I17: =IF(AND(F17>0,G17>0),F17/G17,"")
A18: 104 | B18: 1 | C18: mule deer | D18: 2021 | E18: 1283 | F18: 10730 | G18: 57 | H18: =IF(E18>0,G18/E18,"") | I18: =IF(AND(F18>0,G18>0),F18/G18,"")
A19: 104 | B19: 1 | C19: mule deer | D19: 2022 | G19: 39 | H19: =IF(E19>0,G19/E19,"") | I19: =IF(AND(F19>0,G19>0),F19/G19,"")
A20: 104 | B20: 1 | C20: mule deer | D20: 2023 | E20: 1264 | F20: 9592 | G20: 59 | H20: =IF(E20>0,G20/E20,"") | I20: =IF(AND(F20>0,G20>0),F20/G20,"")
A21: 104 | B21: 1 | C21: mule deer | D21: 2024 | G21: 66 | H21: =IF(E21>0,G21/E21,"") | I21: =IF(AND(F21>0,G21>0),F21/G21,"")
A22: 104 | B22: 1 | C22: mule deer | D22: 2025 | E22: 1575 | F22: 12880 | G22: 64 | H22: =IF(E22>0,G22/E22,"") | I22: =IF(AND(F22>0,G22>0),F22/G22,"")
A23: 109 | B23: 1 | C23: mule deer | D23: 2021 | E23: 532 | F23: 3607 | G23: 39 | H23: =IF(E23>0,G23/E23,"") | I23: =IF(AND(F23>0,G23>0),F23/G23,"")
A24: 110 | B24: 1 | C24: mule deer | D24: 2021 | E24: 1118 | F24: 6739 | G24: 8 | H24: =IF(E24>0,G24/E24,"") | I24: =IF(AND(F24>0,G24>0),F24/G24,"")
A25: 110 | B25: 1 | C25: mule deer | D25: 2022 | G25: 20 | H25: =IF(E25>0,G25/E25,"") | I25: =IF(AND(F25>0,G25>0),F25/G25,"")
A26: 110 | B26: 1 | C26: mule deer | D26: 2023 | E26: 1360 | F26: 7975 | G26: 40 | H26: =IF(E26>0,G26/E26,"") | I26: =IF(AND(F26>0,G26>0),F26/G26,"")
A27: 110 | B27: 1 | C27: mule deer | D27: 2024 | G27: 25 | H27: =IF(E27>0,G27/E27,"") | I27: =IF(AND(F27>0,G27>0),F27/G27,"")
A28: 110 | B28: 1 | C28: mule deer | D28: 2025 | E28: 1344 | F28: 8403 | G28: 38 | H28: =IF(E28>0,G28/E28,"") | I28: =IF(AND(F28>0,G28>0),F28/G28,"")
A29: 120 | B29: 1 | C29: mule deer | D29: 2021 | E29: 1956 | F29: 12140 | G29: 36 | H29: =IF(E29>0,G29/E29,"") | I29: =IF(AND(F29>0,G29>0),F29/G29,"")
A30: 120 | B30: 1 | C30: mule deer | D30: 2022 | G30: 49 | H30: =IF(E30>0,G30/E30,"") | I30: =IF(AND(F30>0,G30>0),F30/G30,"")
A31: 120 | B31: 1 | C31: mule deer | D31: 2023 | E31: 2206 | F31: 14981 | G31: 47 | H31: =IF(E31>0,G31/E31,"") | I31: =IF(AND(F31>0,G31>0),F31/G31,"")
A32: 120 | B32: 1 | C32: mule deer | D32: 2024 | G32: 34 | H32: =IF(E32>0,G32/E32,"") | I32: =IF(AND(F32>0,G32>0),F32/G32,"")
A33: 120 | B33: 1 | C33: mule deer | D33: 2025 | E33: 2179 | F33: 14543 | G33: 52 | H33: =IF(E33>0,G33/E33,"") | I33: =IF(AND(F33>0,G33>0),F33/G33,"")
A34: 121 | B34: 1 | C34: mule deer | D34: 2021 | E34: 2404 | F34: 20248 | G34: 130 | H34: =IF(E34>0,G34/E34,"") | I34: =IF(AND(F34>0,G34>0),F34/G34,"")
A35: 121 | B35: 1 | C35: mule deer | D35: 2022 | G35: 120 | H35: =IF(E35>0,G35/E35,"") | I35: =IF(AND(F35>0,G35>0),F35/G35,"")
A36: 121 | B36: 1 | C36: mule deer | D36: 2023 | E36: 2551 | F36: 21482 | G36: 131 | H36: =IF(E36>0,G36/E36,"") | I36: =IF(AND(F36>0,G36>0),F36/G36,"")
A37: 121 | B37: 1 | C37: mule deer | D37: 2024 | G37: 169 | H37: =IF(E37>0,G37/E37,"") | I37: =IF(AND(F37>0,G37>0),F37/G37,"")
A38: 121 | B38: 1 | C38: mule deer | D38: 2025 | E38: 2639 | F38: 22986 | G38: 176 | H38: =IF(E38>0,G38/E38,"") | I38: =IF(AND(F38>0,G38>0),F38/G38,"")
A39: 122 | B39: 1 | C39: mule deer | D39: 2021 | E39: 1896 | F39: 15178 | G39: 123 | H39: =IF(E39>0,G39/E39,"") | I39: =IF(AND(F39>0,G39>0),F39/G39,"")
A40: 122 | B40: 1 | C40: mule deer | D40: 2022 | G40: 158 | H40: =IF(E40>0,G40/E40,"") | I40: =IF(AND(F40>0,G40>0),F40/G40,"")
...
