Workbook

Sheet Summary
A1: Montana big game harvest, statewide
A2: Totals are formulas over the Data sheet, so they update if you edit it.
A4: Year | B4: Mule Deer | C4: Whitetail | D4: Elk | E4: Antelope
A5: 2004 | B5: =SUMIFS(Data!$H$2:$H$11723,Data!$C$2:$C$11723,"mule deer",Data!$D$2:$D$11723,$A5) | C5: =SUMIFS(Data!$H$2:$H$11723,Data!$C$2:$C$11723,"whitetail",Data!$D$2:$D$11723,$A5) | D5: =SUMIFS(Data!$H$2:$H$11723,Data!$C$2:$C$11723,"elk",Data!$D$2:$D$11723,$A5) | E5: =SUMIFS(Data!$H$2:$H$11723,Data!$C$2:$C$11723,"antelope",Data!$D$2:$D$11723,$A5)
A6: 2005 | B6: =SUMIFS(Data!$H$2:$H$11723,Data!$C$2:$C$11723,"mule deer",Data!$D$2:$D$11723,$A6) | C6: =SUMIFS(Data!$H$2:$H$11723,Data!$C$2:$C$11723,"whitetail",Data!$D$2:$D$11723,$A6) | D6: =SUMIFS(Data!$H$2:$H$11723,Data!$C$2:$C$11723,"elk",Data!$D$2:$D$11723,$A6) | E6: =SUMIFS(Data!$H$2:$H$11723,Data!$C$2:$C$11723,"antelope",Data!$D$2:$D$11723,$A6)
A7: 2006 | B7: =SUMIFS(Data!$H$2:$H$11723,Data!$C$2:$C$11723,"mule deer",Data!$D$2:$D$11723,$A7) | C7: =SUMIFS(Data!$H$2:$H$11723,Data!$C$2:$C$11723,"whitetail",Data!$D$2:$D$11723,$A7) | D7: =SUMIFS(Data!$H$2:$H$11723,Data!$C$2:$C$11723,"elk",Data!$D$2:$D$11723,$A7) | E7: =SUMIFS(Data!$H$2:$H$11723,Data!$C$2:$C$11723,"antelope",Data!$D$2:$D$11723,$A7)
A8: 2007 | B8: =SUMIFS(Data!$H$2:$H$11723,Data!$C$2:$C$11723,"mule deer",Data!$D$2:$D$11723,$A8) | C8: =SUMIFS(Data!$H$2:$H$11723,Data!$C$2:$C$11723,"whitetail",Data!$D$2:$D$11723,$A8) | D8: =SUMIFS(Data!$H$2:$H$11723,Data!$C$2:$C$11723,"elk",Data!$D$2:$D$11723,$A8) | E8: =SUMIFS(Data!$H$2:$H$11723,Data!$C$2:$C$11723,"antelope",Data!$D$2:$D$11723,$A8)
A9: 2008 | B9: =SUMIFS(Data!$H$2:$H$11723,Data!$C$2:$C$11723,"mule deer",Data!$D$2:$D$11723,$A9) | C9: =SUMIFS(Data!$H$2:$H$11723,Data!$C$2:$C$11723,"whitetail",Data!$D$2:$D$11723,$A9) | D9: =SUMIFS(Data!$H$2:$H$11723,Data!$C$2:$C$11723,"elk",Data!$D$2:$D$11723,$A9) | E9: =SUMIFS(Data!$H$2:$H$11723,Data!$C$2:$C$11723,"antelope",Data!$D$2:$D$11723,$A9)
A10: 2009 | B10: =SUMIFS(Data!$H$2:$H$11723,Data!$C$2:$C$11723,"mule deer",Data!$D$2:$D$11723,$A10) | C10: =SUMIFS(Data!$H$2:$H$11723,Data!$C$2:$C$11723,"whitetail",Data!$D$2:$D$11723,$A10) | D10: =SUMIFS(Data!$H$2:$H$11723,Data!$C$2:$C$11723,"elk",Data!$D$2:$D$11723,$A10) | E10: =SUMIFS(Data!$H$2:$H$11723,Data!$C$2:$C$11723,"antelope",Data!$D$2:$D$11723,$A10)
A11: 2010 | B11: =SUMIFS(Data!$H$2:$H$11723,Data!$C$2:$C$11723,"mule deer",Data!$D$2:$D$11723,$A11) | C11: =SUMIFS(Data!$H$2:$H$11723,Data!$C$2:$C$11723,"whitetail",Data!$D$2:$D$11723,$A11) | D11: =SUMIFS(Data!$H$2:$H$11723,Data!$C$2:$C$11723,"elk",Data!$D$2:$D$11723,$A11) | E11: =SUMIFS(Data!$H$2:$H$11723,Data!$C$2:$C$11723,"antelope",Data!$D$2:$D$11723,$A11)
A12: 2011 | B12: =SUMIFS(Data!$H$2:$H$11723,Data!$C$2:$C$11723,"mule deer",Data!$D$2:$D$11723,$A12) | C12: =SUMIFS(Data!$H$2:$H$11723,Data!$C$2:$C$11723,"whitetail",Data!$D$2:$D$11723,$A12) | D12: =SUMIFS(Data!$H$2:$H$11723,Data!$C$2:$C$11723,"elk",Data!$D$2:$D$11723,$A12) | E12: =SUMIFS(Data!$H$2:$H$11723,Data!$C$2:$C$11723,"antelope",Data!$D$2:$D$11723,$A12)
A13: 2012 | B13: =SUMIFS(Data!$H$2:$H$11723,Data!$C$2:$C$11723,"mule deer",Data!$D$2:$D$11723,$A13) | C13: =SUMIFS(Data!$H$2:$H$11723,Data!$C$2:$C$11723,"whitetail",Data!$D$2:$D$11723,$A13) | D13: =SUMIFS(Data!$H$2:$H$11723,Data!$C$2:$C$11723,"elk",Data!$D$2:$D$11723,$A13) | E13: =SUMIFS(Data!$H$2:$H$11723,Data!$C$2:$C$11723,"antelope",Data!$D$2:$D$11723,$A13)
A14: 2013 | B14: =SUMIFS(Data!$H$2:$H$11723,Data!$C$2:$C$11723,"mule deer",Data!$D$2:$D$11723,$A14) | C14: =SUMIFS(Data!$H$2:$H$11723,Data!$C$2:$C$11723,"whitetail",Data!$D$2:$D$11723,$A14) | D14: =SUMIFS(Data!$H$2:$H$11723,Data!$C$2:$C$11723,"elk",Data!$D$2:$D$11723,$A14) | E14: =SUMIFS(Data!$H$2:$H$11723,Data!$C$2:$C$11723,"antelope",Data!$D$2:$D$11723,$A14)
A15: 2014 | B15: =SUMIFS(Data!$H$2:$H$11723,Data!$C$2:$C$11723,"mule deer",Data!$D$2:$D$11723,$A15) | C15: =SUMIFS(Data!$H$2:$H$11723,Data!$C$2:$C$11723,"whitetail",Data!$D$2:$D$11723,$A15) | D15: =SUMIFS(Data!$H$2:$H$11723,Data!$C$2:$C$11723,"elk",Data!$D$2:$D$11723,$A15) | E15: =SUMIFS(Data!$H$2:$H$11723,Data!$C$2:$C$11723,"antelope",Data!$D$2:$D$11723,$A15)
A16: 2015 | B16: =SUMIFS(Data!$H$2:$H$11723,Data!$C$2:$C$11723,"mule deer",Data!$D$2:$D$11723,$A16) | C16: =SUMIFS(Data!$H$2:$H$11723,Data!$C$2:$C$11723,"whitetail",Data!$D$2:$D$11723,$A16) | D16: =SUMIFS(Data!$H$2:$H$11723,Data!$C$2:$C$11723,"elk",Data!$D$2:$D$11723,$A16) | E16: =SUMIFS(Data!$H$2:$H$11723,Data!$C$2:$C$11723,"antelope",Data!$D$2:$D$11723,$A16)
... A26: 2025 | B26: =SUMIFS(Data!$H$2:$H$11723,Data!$C$2:$C$11723,"mule deer",Data!$D$2:$D$11723,$A26) | C26: =SUMIFS(Data!$H$2:$H$11723,Data!$C$2:$C$11723,"whitetail",Data!$D$2:$D$11723,$A26) | D26: =SUMIFS(Data!$H$2:$H$11723,Data!$C$2:$C$11723,"elk",Data!$D$2:$D$11723,$A26) | E26: =SUMIFS(Data!$H$2:$H$11723,Data!$C$2:$C$11723,"antelope",Data!$D$2:$D$11723,$A26)
A28: Source: Montana FWP harvest estimates (myfwp.mt.gov).
A29: Hunter numbers are surveyed every other year: deer in odd years, elk and antelope in even years.
A30: General = buck/bull on a general license. Draw = buck/bull needs a permit or license from a drawing (lottery).
A31: Antelope districts use their own numbering. Antelope licenses are all by drawing.

Sheet Top Districts
A1: Best-odds districts by species
A2: Ranked by harvest per hunter, districts with 100+ hunters, using each species' latest surveyed year. Draw districts usually rank high because hunter numbers are capped.
A4: Mule Deer, 2025 | I4: Whitetail, 2025 | Q4: Elk, 2024 | Y4: Antelope, 2024
A5: # | B5: District | C5: License | D5: Hunters | E5: Harvest | F5: Bucks | G5: Per hunter | I5: # | J5: District | K5: License | L5: Hunters | M5: Harvest | N5: Bucks | O5: Per hunter | Q5: # | R5: District | S5: License | T5: Hunters | U5: Harvest | V5: Bulls | W5: Per hunter | Y5: # | Z5: District | AA5: License | AB5: Hunters | AC5: Harvest | AD5: Bucks | AE5: Per hunter
A6: 1 | B6: 392 | C6: Draw | D6: 691 | E6: 327 | F6: 290 | G6: =E6/D6 | I6: 1 | J6: 170 | K6: General | L6: 2713 | M6: 1750 | N6: 808 | O6: =M6/L6 | Q6: 1 | R6: 455 | S6: Draw | T6: 317 | U6: 148 | V6: 48 | W6: =U6/T6 | Y6: 1 | Z6: 705 | AA6: Draw | AB6: 1714 | AC6: 1594 | AD6: 1044 | AE6: =AC6/AB6
A7: 2 | B7: 405 | C7: General | D7: 1279 | E7: 588 | F7: 380 | G7: =E7/D7 | I7: 2 | J7: 444 | K7: General | L7: 840 | M7: 491 | N7: 265 | O7: =M7/L7 | Q7: 2 | R7: 417 | S7: Draw | T7: 662 | U7: 292 | V7: 185 | W7: =U7/T7 | Y7: 2 | Z7: 440 | AA7: Draw | AB7: 176 | AC7: 143 | AD7: 71 | AE7: =AC7/AB7
A8: 3 | B8: 471 | C8: General | D8: 640 | E8: 284 | F8: 266 | G8: =E8/D8 | I8: 3 | J8: 260 | K8: General | L8: 1130 | M8: 633 | N8: 215 | O8: =M8/L8 | Q8: 3 | R8: 580S | S8: General | T8: 477 | U8: 198 | V8: 80 | W8: =U8/T8 | Y8: 3 | Z8: 340 | AA8: Draw | AB8: 417 | AC8: 335 | AD8: 174 | AE8: =AC8/AB8
A9: 4 | B9: 640 | C9: General | D9: 2776 | E9: 1225 | F9: 993 | G9: =E9/D9 | I9: 4 | J9: 445 | K9: General | L9: 1281 | M9: 658 | N9: 296 | O9: =M9/L9 | Q9: 4 | R9: 445 | S9: General | T9: 847 | U9: 350 | V9: 147 | W9: =U9/T9 | Y9: 4 | Z9: 586 | AA9: Draw | AB9: 392 | AC9: 306 | AD9: 203 | AE9: =AC9/AB9
A10: 5 | B10: 403 | C10: General | D10: 418 | E10: 183 | F10: 137 | G10: =E10/D10 | I10: 5 | J10: 309 | K10: General | L10: 802 | M10: 346 | N10: 174 | O10: =M10/L10 | Q10: 5 | R10: 411W | S10: General | T10: 902 | U10: 355 | V10: 156 | W10: =U10/T10 | Y10: 5 | Z10: 650 | AA10: Draw | AB10: 459 | AC10: 344 | AD10: 264 | AE10: =AC10/AB10
A11: 6 | B11: 652 | C11: Draw | D11: 123 | E11: 52 | F11: 48 | G11: =E11/D11 | I11: 6 | J11: 262 | K11: General | L11: 804 | M11: 327 | N11: 172 | O11: =M11/L11 | Q11: 6 | R11: 250 | S11: Draw | T11: 130 | U11: 51 | V11: 36 | W11: =U11/T11 | Y11: 6 | Z11: 620 | AA11: Draw | AB11: 434 | AC11: 310 | AD11: 264 | AE11: =AC11/AB11
A12: 7 | B12: 650 | C12: General | D12: 2010 | E12: 843 | F12: 796 | G12: =E12/D12 | I12: 7 | J12: 311 | K12: General | L12: 1633 | M12: 653 | N12: 298 | O12: =M12/L12 | Q12: 7 | R12: 411E | S12: General | T12: 1381 | U12: 534 | V12: 220 | W12: =U12/T12 | Y12: 7 | Z12: 690 | AA12: Draw | AB12: 341 | AC12: 239 | AD12: 171 | AE12: =AC12/AB12
A13: 8 | B13: 704 | C13: General | D13: 4306 | E13: 1770 | F13: 1720 | G13: =E13/D13 | I13: 8 | J13: 121 | K13: General | L13: 2639 | M13: 979 | N13: 868 | O13: =M13/L13 | Q13: 8 | R13: 700 | S13: Draw | T13: 1757 | U13: 660 | V13: 294 | W13: =U13/T13 | Y13: 8 | Z13: 670 | AA13: Draw | AB13: 314 | AC13: 220 | AD13: 187 | AE13: =AC13/AB13
A14: 9 | B14: 690 | C14: General | D14: 2914 | E14: 1194 | F14: 1087 | G14: =E14/D14 | I14: 9 | J14: 100 | K14: General | L14: 2765 | M14: 1021 | N14: 750 | O14: =M14/L14 | Q14: 9 | R14: 702 | S14: General | T14: 771 | U14: 284 | V14: 102 | W14: =U14/T14 | Y14: 9 | Z14: 430 | AA14: Draw | AB14: 214 | AC14: 148 | AD14: 112 | AE14: =AC14/AB14
A15: 10 | B15: 705 | C15: General | D15: 3585 | E15: 1463 | F15: 1409 | G15: =E15/D15 | I15: 10 | J15: 101 | K15: General | L15: 2913 | M15: 1066 | N15: 770 | O15: =M15/L15 | Q15: 10 | R15: 580N | S15: General | T15: 1353 | U15: 482 | V15: 186 | W15: =U15/T15 | Y15: 10 | Z15: 700 | AA15: Draw | AB15: 1385 | AC15: 956 | AD15: 791 | AE15: =AC15/AB15
A16: 11 | B16: 426 | C16: General | D16: 835 | E16: 335 | F16: 316 | G16: =E16/D16 | I16: 11 | J16: 261 | K16: General | L16: 486 | M16: 174 | N16: 140 | O16: =M16/L16 | Q16: 11 | R16: 446 | S16: General | T16: 1140 | U16: 399 | V16: 167 | W16: =U16/T16 | Y16: 11 | Z16: 480 | AA16: Draw | AB16: 173 | AC16: 118 | AD16: 100 | AE16: =AC16/AB16
A17: 12 | B17: 502 | C17: General | D17: 1625 | E17: 650 | F17: 552 | G17: =E17/D17 | I17: 12 | J17: 580 | K17: General | L17: 1399 | M17: 496 | N17: 254 | O17: =M17/L17 | Q17: 12 | R17: 317 | S17: General | T17: 1303 | U17: 437 | V17: 94 | W17: =U17/T17 | Y17: 12 | Z17: 701 | AA17: Draw | AB17: 1093 | AC17: 728 | AD17: 627 | AE17: =AC17/AB17
... A30: 25 | B30: 700 | C30: General | D30: 3259 | E30: 1015 | F30: 886 | G30: =E30/D30 | I30: 25 | J30: 104 | K30: General | L30: 1575 | M30: 469 | N30: 337 | O30: =M30/L30 | Q30: 25 | R30: 393 | S30: General | T30: 2048 | U30: 590 | V30: 237 | W30: =U30/T30 | Y30: 25 | Z30: 420 | AA30: Draw | AB30: 178 | AC30: 103 | AD30: 81 | AE30: =AC30/AB30

Sheet Trends
A1: Harvest by district and year
A2: Darker green = more animals taken (shaded per species). Change compares the first and latest year.
A4: Mule Deer
A5: District | B5: License | C5: 2004 | D5: 2005 | E5: 2006 | F5: 2007 | G5: 2008 | H5: 2009 | I5: 2010 | J5: 2011 | K5: 2012 | L5: 2013 | M5: 2014 | N5: 2015 | O5: 2016 | P5: 2017 | Q5: 2018 | R5: 2019 | S5: 2020 | T5: 2021 | U5: 2022 | V5: 2023 | W5: 2024 | X5: 2025 | Y5: Change
A6: 100 | B6: General | C6: 222 | D6: 258 | E6: 245 | F6: 187 | G6: 180 | H6: 198 | I6: 194 | J6: 91 | K6: 128 | L6: 119 | M6: 158 | N6: 115 | O6: 212 | P6: 97 | Q6: 66 | R6: 104 | S6: 137 | T6: 165 | U6: 176 | V6: 169 | W6: 113 | X6: 119 | Y6: =IF(AND(ISNUMBER(C6),C6>0,ISNUMBER(X6)),X6/C6-1,"")
A7: 101 | B7: General | C7: 204 | D7: 203 | E7: 170 | F7: 122 | G7: 87 | H7: 71 | I7: 133 | J7: 73 | K7: 81 | L7: 90 | M7: 93 | N7: 57 | O7: 121 | P7: 50 | Q7: 63 | R7: 88 | S7: 66 | T7: 74 | U7: 110 | V7: 106 | W7: 125 | X7: 92 | Y7: =IF(AND(ISNUMBER(C7),C7>0,ISNUMBER(X7)),X7/C7-1,"")
A8: 102 | C8: 100 | D8: 137 | E8: 129 | F8: 103 | G8: 102 | H8: 48 | I8: 71 | J8: 52 | K8: 48 | L8: 91 | M8: 43 | N8: 49 | O8: 79 | P8: 41 | Q8: 28 | R8: 45 | S8: 27 | T8: 54 | Y8: =IF(AND(ISNUMBER(C8),C8>0,ISNUMBER(X8)),X8/C8-1,"")
A9: 103 | B9: General | C9: 418 | D9: 320 | E9: 256 | F9: 249 | G9: 152 | H9: 172 | I9: 156 | J9: 124 | K9: 140 | L9: 155 | M9: 153 | N9: 115 | O9: 184 | P9: 119 | Q9: 112 | R9: 120 | S9: 159 | T9: 138 | U9: 158 | V9: 207 | W9: 233 | X9: 212 | Y9: =IF(AND(ISNUMBER(C9),C9>0,ISNUMBER(X9)),X9/C9-1,"")
A10: 104 | B10: General | C10: 150 | D10: 166 | E10: 119 | F10: 108 | G10: 106 | H10: 80 | I10: 89 | J10: 49 | K10: 56 | L10: 79 | M10: 85 | N10: 83 | O10: 64 | P10: 29 | Q10: 70 | R10: 62 | S10: 81 | T10: 57 | U10: 39 | V10: 59 | W10: 66 | X10: 64 | Y10: =IF(AND(ISNUMBER(C10),C10>0,ISNUMBER(X10)),X10/C10-1,"")
A11: 109 | C11: 74 | D11: 87 | E11: 66 | F11: 42 | G11: 37 | H11: 89 | I11: 50 | J11: 26 | K11: 11 | L11: 25 | M11: 18 | N11: 39 | O11: 21 | P11: 12 | Q11: 37 | R11: 25 | S11: 55 | T11: 39 | Y11: =IF(AND(ISNUMBER(C11),C11>0,ISNUMBER(X11)),X11/C11-1,"")
A12: 110 | B12: General | C12: 104 | D12: 182 | E12: 165 | F12: 90 | G12: 75 | H12: 89 | I12: 76 | J12: 25 | K12: 31 | L12: 68 | M12: 26 | N12: 26 | O12: 53 | P12: 30 | Q12: 38 | R12: 14 | S12: 30 | T12: 8 | U12: 20 | V12: 40 | W12: 25 | X12: 38 | Y12: =IF(AND(ISNUMBER(C12),C12>0,ISNUMBER(X12)),X12/C12-1,"")
A13: 120 | B13: General | C13: 66 | D13: 93 | E13: 96 | F13: 103 | G13: 39 | H13: 67 | I13: 48 | J13: 43 | K13: 53 | L13: 40 | M13: 31 | N13: 42 | O13: 61 | P13: 19 | Q13: 28 | R13: 43 | S13: 37 | T13: 36 | U13: 49 | V13: 47 | W13: 34 | X13: 52 | Y13: =IF(AND(ISNUMBER(C13),C13>0,ISNUMBER(X13)),X13/C13-1,"")
A14: 121 | B14: General | C14: 157 | D14: 256 | E14: 219 | F14: 187 | G14: 232 | H14: 128 | I14: 164 | J14: 118 | K14: 117 | L14: 97 | M14: 110 | N14: 98 | O14: 179 | P14: 92 | Q14: 106 | R14: 119 | S14: 72 | T14: 130 | U14: 120 | V14: 131 | W14: 169 | X14: 176 | Y14: =IF(AND(ISNUMBER(C14),C14>0,ISNUMBER(X14)),X14/C14-1,"")
A15: 122 | B15: General | C15: 208 | D15: 201 | E15: 115 | F15: 176 | G15: 152 | H15: 117 | I15: 135 | J15: 116 | K15: 106 | L15: 120 | M15: 129 | N15: 172 | O15: 175 | P15: 106 | Q15: 113 | R15: 151 | S15: 117 | T15: 123 | U15: 158 | V15: 189 | W15: 201 | X15: 160 | Y15: =IF(AND(ISNUMBER(C15),C15>0,ISNUMBER(X15)),X15/C15-1,"")
A16: 123 | B16: General | C16: 49 | D16: 51 | E16: 71 | F16: 32 | G16: 46 | H16: 59 | I16: 51 | J16: 27 | K16: 53 | L16: 25 | M16: 45 | N16: 20 | O16: 87 | P16: 26 | Q16: 46 | R16: 50 | S16: 13 | T16: 19 | U16: 26 | V16: 47 | W16: 72 | X16: 53 | Y16: =IF(AND(ISNUMBER(C16),C16>0,ISNUMBER(X16)),X16/C16-1,"")
A17: 124 | B17: General | C17: 42 | D17: 47 | E17: 82 | F17: 53 | G17: 52 | H17: 39 | I17: 44 | J17: 33 | K17: 47 | L17: 45 | M17: 39 | N17: 29 | O17: 60 | P17: 53 | Q17: 41 | R17: 50 | S17: 44 | T17: 27 | U17: 71 | V17: 65 | W17: 53 | X17: 75 | Y17: =IF(AND(ISNUMBER(C17),C17>0,ISNUMBER(X17)),X17/C17-1,"")
A18: 130 | B18: General | C18: 60 | D18: 52 | E18: 34 | F18: 45 | G18: 44 | H18: 35 | I18: 45 | J18: 17 | K18: 44 | L18: 20 | M18: 27 | N18: 24 | O18: 56 | P18: 34 | Q18: 33 | R18: 3 | S18: 33 | T18: 14 | U18: 33 | V18: 20 | W18: 32 | X18: 45 | Y18: =IF(AND(ISNUMBER(C18),C18>0,ISNUMBER(X18)),X18/C18-1,"")
A19: 132 | C19: 44 | D19: 24 | E19: 43 | F19: 29 | G19: 38 | H19: 27 | I19: 23 | J19: 15 | K19: 11 | L19: 37 | M19: 47 | N19: 14 | O19: 36 | P19: 30 | Q19: 22 | R19: 33 | Y19: =IF(AND(ISNUMBER(C19),C19>0,ISNUMBER(X19)),X19/C19-1,"")
A20: 140 | B20: General | C20: 90 | D20: 53 | E20: 67 | F20: 60 | G20: 45 | H20: 53 | I20: 20 | J20: 20 | K20: 45 | L20: 28 | M20: 31 | N20: 23 | O20: 40 | P20: 21 | Q20: 9 | R20: 18 | S20: 10 | T20: 28 | U20: 36 | V20: 44 | W20: 31 | X20: 33 | Y20: =IF(AND(ISNUMBER(C20),C20>0,ISNUMBER(X20)),X20/C20-1,"")
A21: 141 | B21: General | C21: 26 | D21: 38 | E21: 7 | F21: 19 | G21: 12 | H21: 9 | I21: 14 | K21: 6 | L21: 6 | M21: 9 | N21: 6 | O21: 3 | P21: 9 | Q21: 3 | R21: 3 | T21: 11 | U21: 7 | V21: 10 | W21: 3 | X21: 7 | Y21: =IF(AND(ISNUMBER(C21),C21>0,ISNUMBER(X21)),X21/C21-1,"")
A22: 150 | B22: General | C22: 50 | D22: 97 | E22: 108 | F22: 58 | G22: 40 | H22: 24 | I22: 30 | J22: 17 | K22: 31 | L22: 58 | M22: 23 | N22: 20 | O22: 15 | P22: 23 | S22: 7 | T22: 8 | U22: 10 | V22: 9 | W22: 12 | X22: 10 | Y22: =IF(AND(ISNUMBER(C22),C22>0,ISNUMBER(X22)),X22/C22-1,"")
A23: 151 | C23: 11 | D23: 13 | E23: 19 | F23: 6 | G23: 15 | H23: 20 | I23: 8 | K23: 3 | L23: 3 | N23: 3 | P23: 6 | Q23: 3 | R23: 6 | Y23: =IF(AND(ISNUMBER(C23),C23>0,ISNUMBER(X23)),X23/C23-1,"")
A24: 170 | B24: General | C24: 17 | D24: 23 | E24: 42 | F24: 20 | G24: 41 | H24: 41 | I24: 21 | J24: 31 | K24: 18 | L24: 3 | M24: 28 | N24: 26 | O24: 27 | P24: 27 | Q24: 23 | R24: 39 | S24: 14 | T24: 48 | U24: 40 | V24: 44 | W24: 36 | X24: 22 | Y24: =IF(AND(ISNUMBER(C24),C24>0,ISNUMBER(X24)),X24/C24-1,"")
A25: 200 | B25: General | C25: 43 | D25: 58 | E25: 54 | F25: 43 | G25: 61 | H25: 17 | I25: 42 | J25: 20 | K25: 22 | L25: 17 | M25: 26 | N25: 12 | O25: 45 | P25: 30 | Q25: 43 | R25: 47 | S25: 39 | T25: 23 | U25: 10 | V25: 45 | W25: 34 | X25: 28 | Y25: =IF(AND(ISNUMBER(C25),C25>0,ISNUMBER(X25)),X25/C25-1,"")
A26: 201 | B26: General | C26: 131 | D26: 104 | E26: 185 | F26: 87 | G26: 114 | H26: 77 | I26: 79 | J26: 67 | K26: 64 | L26: 76 | M26: 59 | N26: 79 | O26: 121 | P26: 34 | Q26: 68 | R26: 96 | S26: 60 | T26: 87 | U26: 166 | V26: 211 | W26: 205 | X26: 185 | Y26: =IF(AND(ISNUMBER(C26),C26>0,ISNUMBER(X26)),X26/C26-1,"")
A27: 202 | B27: Draw | C27: 117 | D27: 98 | E27: 98 | F27: 91 | G27: 77 | H27: 61 | I27: 100 | J27: 48 | K27: 83 | L27: 74 | M27: 79 | N27: 81 | O27: 121 | P27: 81 | Q27: 88 | R27: 108 | S27: 104 | T27: 95 | U27: 67 | V27: 83 | W27: 99 | X27: 104 | Y27: =IF(AND(ISNUMBER(C27),C27>0,ISNUMBER(X27)),X27/C27-1,"")
A28: 203 | C28: 122 | D28: 128 | E28: 145 | F28: 139 | G28: 57 | H28: 68 | I28: 87 | J28: 115 | K28: 84 | L28: 73 | M28: 136 | N28: 121 | O28: 160 | P28: 118 | Q28: 128 | R28: 119 | S28: 134 | T28: 96 | Y28: =IF(AND(ISNUMBER(C28),C28>0,ISNUMBER(X28)),X28/C28-1,"")
A29: 204 | B29: General | C29: 146 | D29: 137 | E29: 259 | F29: 106 | G29: 142 | H29: 89 | I29: 123 | J29: 129 | K29: 176 | L29: 146 | M29: 197 | N29: 166 | O29: 155 | P29: 147 | Q29: 109 | R29: 92 | S29: 70 | T29: 72 | U29: 95 | V29: 138 | W29: 67 | X29: 92 | Y29: =IF(AND(ISNUMBER(C29),C29>0,ISNUMBER(X29)),X29/C29-1,"")
A30: 210 | B30: Draw | C30: 68 | D30: 112 | E30: 86 | F30: 115 | G30: 58 | H30: 77 | I30: 77 | J30: 64 | K30: 57 | L30: 54 | M30: 47 | N30: 44 | O30: 48 | P30: 50 | Q30: 63 | R30: 46 | S30: 70 | T30: 49 | U30: 57 | V30: 67 | W30: 74 | X30: 62 | Y30: =IF(AND(ISNUMBER(C30),C30>0,ISNUMBER(X30)),X30/C30-1,"")
A31: 211 | B31: General | C31: 44 | D31: 37 | E31: 37 | F31: 33 | G31: 21 | H31: 17 | I31: 3 | J31: 14 | K31: 22 | L31: 17 | M31: 34 | N31: 19 | O31: 36 | P31: 27 | Q31: 25 | R31: 20 | S31: 24 | T31: 35 | U31: 31 | V31: 40 | W31: 53 | X31: 37 | Y31: =IF(AND(ISNUMBER(C31),C31>0,ISNUMBER(X31)),X31/C31-1,"")
A32: 212 | B32: General | C32: 263 | D32: 332 | E32: 343 | F32: 180 | G32: 90 | H32: 155 | I32: 178 | J32: 170 | K32: 212 | L32: 240 | M32: 179 | N32: 265 | O32: 173 | P32: 148 | Q32: 88 | R32: 86 | S32: 55 | T32: 38 | U32: 49 | V32: 43 | W32: 62 | X32: 79 | Y32: =IF(AND(ISNUMBER(C32),C32>0,ISNUMBER(X32)),X32/C32-1,"")
A33: 213 | B33: General | C33: 51 | D33: 95 | E33: 98 | F33: 56 | G33: 51 | H33: 45 | I33: 67 | J33: 65 | K33: 117 | L33: 124 | M33: 80 | N33: 121 | O33: 102 | P33: 81 | Q33: 99 | R33: 63 | S33: 141 | T33: 104 | U33: 129 | V33: 145 | W33: 180 | X33: 199 | Y33: =IF(AND(ISNUMBER(C33),C33>0,ISNUMBER(X33)),X33/C33-1,"")
A34: 214 | B34: General | C34: 62 | D34: 107 | E34: 93 | F34: 35 | G34: 29 | H34: 36 | I34: 24 | J34: 30 | K34: 37 | L34: 15 | M34: 26 | N34: 54 | O34: 43 | P34: 22 | Q34: 30 | R34: 32 | S34: 23 | T34: 16 | U34: 20 | V34: 27 | W34: 45 | X34: 14 | Y34: =IF(AND(ISNUMBER(C34),C34>0,ISNUMBER(X34)),X34/C34-1,"")
A35: 215 | B35: General | C35: 209 | D35: 221 | E35: 242 | F35: 138 | G35: 155 | H35: 168 | I35: 253 | J35: 190 | K35: 107 | L35: 135 | M35: 113 | N35: 164 | O35: 187 | P35: 182 | Q35: 136 | R35: 86 | S35: 100 | T35: 86 | U35: 150 | V35: 140 | W35: 188 | X35: 161 | Y35: =IF(AND(ISNUMBER(C35),C35>0,ISNUMBER(X35)),X35/C35-1,"")
A36: 216 | B36: General | C36: 59 | D36: 92 | E36: 82 | F36: 47 | G36: 42 | H36: 15 | I36: 43 | J36: 25 | K36: 67 | L36: 56 | M36: 65 | N36: 89 | O36: 63 | P36: 80 | Q36: 98 | R36: 73 | S36: 73 | T36: 55 | U36: 74 | V36: 72 | W36: 75 | X36: 90 | Y36: =IF(AND(ISNUMBER(C36),C36>0,ISNUMBER(X36)),X36/C36-1,"")
A37: 217 | B37: General | O37: 31 | P37: 59 | Q37: 57 | R37: 39 | S37: 13 | T37: 44 | U37: 40 | V37: 32 | W37: 44 | X37: 52 | Y37: =IF(AND(ISNUMBER(C37),C37>0,ISNUMBER(X37)),X37/C37-1,"")
A38: 240 | B38: General | C38: 138 | D38: 155 | E38: 249 | F38: 164 | G38: 75 | H38: 81 | I38: 90 | J38: 79 | K38: 81 | L38: 115 | M38: 118 | N38: 106 | O38: 136 | P38: 106 | Q38: 100 | R38: 112 | S38: 120 | T38: 114 | U38: 108 | V38: 114 | W38: 132 | X38: 135 | Y38: =IF(AND(ISNUMBER(C38),C38>0,ISNUMBER(X38)),X38/C38-1,"")
A39: 250 | B39: Draw | C39: 272 | D39: 264 | E39: 274 | F39: 176 | G39: 134 | H39: 88 | I39: 45 | J39: 29 | K39: 40 | L39: 61 | M39: 13 | N39: 21 | O39: 12 | P39: 21 | Q39: 10 | R39: 16 | S39: 14 | T39: 17 | U39: 22 | V39: 23 | W39: 17 | X39: 18 | Y39: =IF(AND(ISNUMBER(C39),C39>0,ISNUMBER(X39)),X39/C39-1,"")
A40: 260 | B40: General | C40: 2 | D40: 7 | E40: 32 | F40: 55 | G40: 21 | H40: 27 | I40: 13 | J40: 6 | K40: 13 | L40: 10 | M40: 17 | N40: 12 | O40: 24 | P40: 21 | Q40: 20 | R40: 24 | S40: 16 | T40: 33 | U40: 42 | V40: 45 | W40: 6 | X40: 35 | Y40: =IF(AND(ISNUMBER(C40),C40>0,ISNUMBER(X40)),X40/C40-1,"")
A41: 261 | B41: Draw | C41: 73 | D41: 93 | E41: 49 | F41: 53 | G41: 67 | H41: 51 | I41: 47 | J41: 81 | K41: 80 | L41: 57 | M41: 33 | N41: 13 | O41: 38 | P41: 42 | Q41: 24 | R41: 19 | S41: 18 | T41: 12 | U41: 14 | V41: 8 | W41: 15 | X41: 9 | Y41: =IF(AND(ISNUMBER(C41),C41>0,ISNUMBER(X41)),X41/C41-1,"")
...

Sheet Regulations
A1: 2026 hunting opportunities by district
A2: Read automatically from FWP's Deer, Elk & Antelope regulations booklet. Always check the official booklet before you hunt.
A4: District | B4: Species | C4: License | D4: How you get it | E4: Legal animal | F4: Archery | G4: General (rifle) | H4: Muzzleloader | I4: Late | J4: Apply by | K4: Quota | L4: Details
A5: 215 | B5: antelope | C5: Antelope License: 215-20 | D5: Drawing | E5: Either-sex Antelope | F5: Sept. 05-Oct. 09 | G5: Oct. 10-Nov. 08 | J5: June 1 | K5: 5
A6: 215 | B6: antelope | C6: Antelope B License: 215-30 | D6: Drawing | E6: Doe/Fawn Antelope | F6: Sept. 05-Oct. 09 | G6: Oct. 10-Nov. 08 | J6: June 1 | K6: 1
A7: 291 | B7: antelope | C7: Antelope License: 291-20 | D7: Drawing | E7: Either-sex Antelope | F7: Sept. 05-Oct. 09 | G7: Oct. 10-Nov. 08 | J7: June 1 | K7: 1
A8: 291 | B8: antelope | C8: Antelope B License: 291-30 | D8: Drawing | E8: Doe/Fawn Antelope | F8: Sept. 05-Oct. 09 | G8: Oct. 10-Nov. 08 | J8: June 1 | K8: 1 | L8: Region
A9: 300 | B9: antelope | C9: Antelope License: 300-20 | D9: Drawing | E9: Either-sex Antelope | F9: Sept. 05-Oct. 09 | G9: Oct. 10-Nov. 08 | J9: June 1 | K9: 125
A10: 300 | B10: antelope | C10: Antelope B License: 300-30 | D10: Drawing | E10: Doe/Fawn Antelope | F10: Sept. 05-Oct. 09 | G10: Oct. 10-Nov. 08 | J10: June 1 | K10: 10
A11: 300 | B11: antelope | C11: Antelope License: 399-20 | D11: Drawing | E11: Either-sex Antelope | G11: Aug. 15-Nov. 08 | J11: June 1 | K11: 500 | L11: First and only choice. ArchEquip only.
A12: 301 | B12: antelope | C12: Antelope License: 301-20 | D12: Drawing | E12: Either-sex Antelope | F12: Sept. 05-Oct. 09 | G12: Oct. 10-Nov. 08 | J12: June 1 | K12: 20
A13: 301 | B13: antelope | C13: Antelope License: 399-20 | D13: Drawing | E13: Either-sex Antelope | G13: Aug. 15-Nov. 08 | J13: June 1 | K13: 500 | L13: First and only choice. ArchEquip only.
A14: 310 | B14: antelope | C14: Antelope License: 310-20 | D14: Drawing | E14: Either-sex Antelope | F14: Sept. 05-Oct. 09 | G14: Oct. 10-Nov. 08 | J14: June 1 | K14: 75
A15: 310 | B15: antelope | C15: Antelope B License: 310-30 | D15: Drawing | E15: Doe/Fawn Antelope | F15: Sept. 05-Oct. 09 | G15: Oct. 10-Nov. 08 | J15: June 1 | K15: 50
A16: 310 | B16: antelope | C16: Antelope License: 399-20 | D16: Drawing | E16: Either-sex Antelope | G16: Aug. 15-Nov. 08 | J16: June 1 | K16: 500 | L16: First and only choice. ArchEquip only.
A17: 311 | B17: antelope | C17: Antelope License: 311-20 | D17: Drawing | E17: Either-sex Antelope | F17: Sept. 05-Oct. 09 | G17: Oct. 10-Nov. 08 | J17: June 1 | K17: 75
A18: 311 | B18: antelope | C18: Antelope License: 399-20 | D18: Drawing | E18: Either-sex Antelope | G18: Aug. 15-Nov. 08 | J18: June 1 | K18: 500 | L18: First and only choice. ArchEquip only.
A19: 313 | B19: antelope | C19: Antelope License: 313-20 | D19: Drawing | E19: Either-sex Antelope | F19: Sept. 05-Oct. 09 | G19: Oct. 10-Nov. 08 | J19: June 1 | K19: 10
A20: 317 | B20: antelope | C20: Antelope License: 317-20 | D20: Drawing | E20: Either-sex Antelope | F20: Sept. 05-Oct. 09 | G20: Oct. 10-Nov. 08 | J20: June 1 | K20: 50
A21: 317 | B21: antelope | C21: Antelope License: 399-20 | D21: Drawing | E21: Either-sex Antelope | G21: Aug. 15-Nov. 08 | J21: June 1 | K21: 500 | L21: First and only choice. ArchEquip only.
A22: 318 | B22: antelope | C22: Antelope License: 318-20 | D22: Drawing | E22: Either-sex Antelope | F22: Sept. 05-Oct. 09 | G22: Oct. 10-Nov. 08 | J22: June 1 | K22: 50
A23: 318 | B23: antelope | C23: Antelope B License: 318-30 | D23: Drawing | E23: Doe/Fawn Antelope | F23: Sept. 05-Oct. 09 | G23: Oct. 10-Nov. 08 | J23: June 1 | K23: 50
A24: 318 | B24: antelope | C24: Antelope License: 399-20 | D24: Drawing | E24: Either-sex Antelope | G24: Aug. 15-Nov. 08 | J24: June 1 | K24: 500 | L24: First and only choice. ArchEquip only.
A25: 319 | B25: antelope | C25: Antelope License: 319-20 | D25: Drawing | E25: Either-sex Antelope | F25: Sept. 05-Oct. 09 | G25: Oct. 10-Nov. 08 | J25: June 1 | K25: 50
A26: 319 | B26: antelope | C26: Antelope B License: 319-30 | D26: Drawing | E26: Doe/Fawn Antelope | F26: Sept. 05-Oct. 09 | G26: Oct. 10-Nov. 08 | J26: June 1 | K26: 50
A27: 319 | B27: antelope | C27: Antelope License: 399-20 | D27: Drawing | E27: Either-sex Antelope | G27: Aug. 15-Nov. 08 | J27: June 1 | K27: 500 | L27: First and only choice. ArchEquip only. 137 2026 Deer • Elk • Antelope Visit fwp.mt.gov
A28: 320 | B28: antelope | C28: Antelope License: 320-20 | D28: Drawing | E28: Either-sex Antelope | F28: Sept. 05-Oct. 09 | G28: Oct. 10-Nov. 08 | J28: June 1 | K28: 25
A29: 320 | B29: antelope | C29: Antelope B License: 320-30 | D29: Drawing | E29: Doe/Fawn Antelope | F29: Sept. 05-Oct. 09 | G29: Oct. 10-Nov. 08 | J29: June 1 | K29: 50
A30: 320 | B30: antelope | C30: Antelope License: 399-20 | D30: Drawing | E30: Either-sex Antelope | G30: Aug. 15-Nov. 08 | J30: June 1 | K30: 500 | L30: First and only choice. ArchEquip only.
A31: 322 | B31: antelope | C31: Antelope License: 322-20 | D31: Drawing | E31: Either-sex Antelope | F31: Sept. 05-Oct. 09 | G31: Oct. 10-Nov. 08 | J31: June 1 | K31: 300
A32: 322 | B32: antelope | C32: Antelope B License: 322-30 | D32: Drawing | E32: Doe/Fawn Antelope | F32: Sept. 05-Oct. 09 | G32: Oct. 10-Nov. 08 | J32: June 1 | K32: 300
A33: 322 | B33: antelope | C33: Antelope License: 399-20 | D33: Drawing | E33: Either-sex Antelope | G33: Aug. 15-Nov. 08 | J33: June 1 | K33: 500 | L33: First and only choice. ArchEquip only.
A34: 329 | B34: antelope | C34: Antelope License: 329-20 | D34: Drawing | E34: Either-sex Antelope | F34: Sept. 05-Oct. 09 | G34: Oct. 10-Nov. 08 | J34: June 1 | K34: 100
A35: 329 | B35: antelope | C35: Antelope License: 399-20 | D35: Drawing | E35: Either-sex Antelope | G35: Aug. 15-Nov. 08 | J35: June 1 | K35: 500 | L35: First and only choice. ArchEquip only.
A36: 338 | B36: antelope | C36: Antelope License: 338-20 | D36: Drawing | E36: Either-sex Antelope | F36: Sept. 05-Oct. 09 | G36: Oct. 10-Nov. 08 | J36: June 1 | K36: 100
A37: 338 | B37: antelope | C37: Antelope License: 399-20 | D37: Drawing | E37: Either-sex Antelope | G37: Aug. 15-Nov. 08 | J37: June 1 | K37: 500 | L37: First and only choice. ArchEquip only.
A38: 339 | B38: antelope | C38: Antelope License: 339-20 | D38: Drawing | E38: Either-sex Antelope | F38: Sept. 05-Oct. 09 | G38: Oct. 10-Nov. 08 | J38: June 1 | K38: 75
A39: 339 | B39: antelope | C39: Antelope License: 399-20 | D39: Drawing | E39: Either-sex Antelope | G39: Aug. 15-Nov. 08 | J39: June 1 | K39: 500 | L39: First and only choice. ArchEquip only.
A40: 340 | B40: antelope | C40: Antelope License: 340-20 | D40: Drawing | E40: Either-sex Antelope | F40: Sept. 05-Oct. 09 | G40: Oct. 10-Nov. 08 | J40: June 1 | K40: 350 | L40: Successful antelope either- sex 340-20 applicants may be ofered the opportunity to purchase one or more doe/fawn 340-30 (Quota: 300, Range 50-500) licenses valid in HD 340 during the same time periods and with the same restrictions.
A41: 340 | B41: antelope | C41: Antelope License: 399-20 | D41: Drawing | E41: Either-sex Antelope | G41: Aug. 15-Nov. 08 | J41: June 1 | K41: 500 | L41: First and only choice. ArchEquip only.
...

Sheet Black Bear
A1: Black bear harvest 2026, season so far
A2: From FWP's quota status page, updated Oct 22, 2026 11:14 AM. FWP doesn't publish multi-year bear harvest by district.
A4: BMU | B4: Status | C4: Closed on | D4: Bears reported | E4: Female harvest | F4: Female quota | G4: Total quota
A5: 100 | B5: OPEN | D5: 17
A6: 101 | B6: OPEN | D6: 9
A7: 103 | B7: OPEN | D7: 22
A8: 104 | B8: OPEN | D8: 15
A9: 110 | B9: OPEN | D9: 4
A10: 120 | B10: OPEN | D10: 17
A11: 121 | B11: OPEN | D11: 25
A12: 122 | B12: OPEN | D12: 27
A13: 123 | B13: OPEN | D13: 12
A14: 130 | B14: OPEN | D14: 12
A15: 140 | B15: OPEN | D15: 6
A16: 141 | B16: OPEN | D16: 4
... A30: 341 | B30: OPEN | D30: 30
A31: 411 | B31: CLOSED | D31: 11 | E31: 5 | F31: 4
A32: 420 | B32: OPEN | D32: 38 | E32: 9 | F32: 10
A33: 440 | B33: OPEN | D33: 16 | E33: 5 | F33: 6
A34: 450 | B34: OPEN | D34: 21 | E34: 7 | F34: 14
A35: 510 | B35: CLOSED | D35: 7 | E35: 2 | F35: 2
A36: 520 | B36: CLOSED | D36: 30 | E36: 15 | F36: 10
A37: 580 | B37: OPEN | D37: 37
A38: 600 | B38: OPEN | D38: 0 | G38: 4
A39: 700 (no hounds) | B39: CLOSED | D39: 19 | G39: 18

Sheet Data
A1: District | B1: Region | C1: Species | D1: Year | E1: License | F1: Hunters | G1: Hunter days | H1: Harvest | I1: Bucks/Bulls | J1: Does/Cows | K1: Per hunter | L1: Days per animal
A2: 215 | B2: 2 | C2: antelope | D2: 2004 | E2: Draw | F2: 37 | G2: 143 | H2: 19 | I2: 6 | J2: 14 | K2: =IF(F2>0,H2/F2,"") | L2: =IF(AND(G2>0,H2>0),G2/H2,"")
A3: 215 | B3: 2 | C3: antelope | D3: 2005 | E3: Draw | F3: 26 | G3: 113 | H3: 17 | I3: 10 | J3: 5 | K3: =IF(F3>0,H3/F3,"") | L3: =IF(AND(G3>0,H3>0),G3/H3,"")
A4: 215 | B4: 2 | C4: antelope | D4: 2006 | E4: Draw | F4: 26 | G4: 57 | H4: 17 | I4: 8 | J4: 9 | K4: =IF(F4>0,H4/F4,"") | L4: =IF(AND(G4>0,H4>0),G4/H4,"")
A5: 215 | B5: 2 | C5: antelope | D5: 2007 | E5: Draw | F5: 29 | G5: 50 | H5: 19 | I5: 6 | J5: 11 | K5: =IF(F5>0,H5/F5,"") | L5: =IF(AND(G5>0,H5>0),G5/H5,"")
A6: 215 | B6: 2 | C6: antelope | D6: 2008 | E6: Draw | F6: 25 | G6: 77 | H6: 23 | I6: 6 | J6: 14 | K6: =IF(F6>0,H6/F6,"") | L6: =IF(AND(G6>0,H6>0),G6/H6,"")
A7: 215 | B7: 2 | C7: antelope | D7: 2009 | E7: Draw | F7: 26 | G7: 124 | H7: 14 | I7: 4 | J7: 9 | K7: =IF(F7>0,H7/F7,"") | L7: =IF(AND(G7>0,H7>0),G7/H7,"")
A8: 215 | B8: 2 | C8: antelope | D8: 2010 | E8: Draw | F8: 51 | G8: 138 | H8: 38 | I8: 19 | J8: 19 | K8: =IF(F8>0,H8/F8,"") | L8: =IF(AND(G8>0,H8>0),G8/H8,"")
A9: 215 | B9: 2 | C9: antelope | D9: 2011 | E9: Draw | F9: 48 | G9: 167 | H9: 34 | I9: 20 | J9: 14 | K9: =IF(F9>0,H9/F9,"") | L9: =IF(AND(G9>0,H9>0),G9/H9,"")
A10: 215 | B10: 2 | C10: antelope | D10: 2012 | E10: Draw | F10: 29 | G10: 121 | H10: 23 | I10: 19 | J10: 4 | K10: =IF(F10>0,H10/F10,"") | L10: =IF(AND(G10>0,H10>0),G10/H10,"")
A11: 215 | B11: 2 | C11: antelope | D11: 2013 | E11: Draw | H11: 18 | I11: 15 | J11: 3 | K11: =IF(F11>0,H11/F11,"") | L11: =IF(AND(G11>0,H11>0),G11/H11,"")
A12: 215 | B12: 2 | C12: antelope | D12: 2014 | E12: Draw | F12: 42 | G12: 112 | H12: 21 | I12: 17 | J12: 4 | K12: =IF(F12>0,H12/F12,"") | L12: =IF(AND(G12>0,H12>0),G12/H12,"")
A13: 215 | B13: 2 | C13: antelope | D13: 2015 | E13: Draw | F13: 34 | G13: 193 | H13: 31 | I13: 26 | J13: 5 | K13: =IF(F13>0,H13/F13,"") | L13: =IF(AND(G13>0,H13>0),G13/H13,"")
A14: 215 | B14: 2 | C14: antelope | D14: 2016 | E14: Draw | H14: 17 | I14: 14 | J14: 3 | K14: =IF(F14>0,H14/F14,"") | L14: =IF(AND(G14>0,H14>0),G14/H14,"")
A15: 215 | B15: 2 | C15: antelope | D15: 2017 | E15: Draw | H15: 42 | I15: 24 | J15: 17 | K15: =IF(F15>0,H15/F15,"") | L15: =IF(AND(G15>0,H15>0),G15/H15,"")
A16: 215 | B16: 2 | C16: antelope | D16: 2018 | E16: Draw | F16: 40 | G16: 40 | H16: 35 | I16: 19 | J16: 16 | K16: =IF(F16>0,H16/F16,"") | L16: =IF(AND(G16>0,H16>0),G16/H16,"")
A17: 215 | B17: 2 | C17: antelope | D17: 2019 | E17: Draw | H17: 27 | I17: 15 | J17: 10 | K17: =IF(F17>0,H17/F17,"") | L17: =IF(AND(G17>0,H17>0),G17/H17,"")
A18: 215 | B18: 2 | C18: antelope | D18: 2020 | E18: Draw | F18: 23 | G18: 78 | H18: 12 | I18: 5 | J18: 7 | K18: =IF(F18>0,H18/F18,"") | L18: =IF(AND(G18>0,H18>0),G18/H18,"")
A19: 215 | B19: 2 | C19: antelope | D19: 2021 | E19: Draw | H19: 5 | I19: 2 | J19: 3 | K19: =IF(F19>0,H19/F19,"") | L19: =IF(AND(G19>0,H19>0),G19/H19,"")
A20: 215 | B20: 2 | C20: antelope | D20: 2022 | E20: Draw | F20: 10 | G20: 100 | H20: 6 | I20: 3 | J20: 4 | K20: =IF(F20>0,H20/F20,"") | L20: =IF(AND(G20>0,H20>0),G20/H20,"")
A21: 215 | B21: 2 | C21: antelope | D21: 2023 | E21: Draw | H21: 2 | I21: 2 | J21: 0 | K21: =IF(F21>0,H21/F21,"") | L21: =IF(AND(G21>0,H21>0),G21/H21,"")
A22: 215 | B22: 2 | C22: antelope | D22: 2024 | E22: Draw | F22: 10 | G22: 28 | H22: 5 | I22: 5 | J22: 0 | K22: =IF(F22>0,H22/F22,"") | L22: =IF(AND(G22>0,H22>0),G22/H22,"")
A23: 215 | B23: 2 | C23: antelope | D23: 2025 | E23: Draw | H23: 3 | I23: 3 | J23: 0 | K23: =IF(F23>0,H23/F23,"") | L23: =IF(AND(G23>0,H23>0),G23/H23,"")
A24: 291 | B24: 2 | C24: antelope | D24: 2008 | E24: Draw | F24: 5 | G24: 5 | H24: 4 | I24: 0 | J24: 4 | K24: =IF(F24>0,H24/F24,"") | L24: =IF(AND(G24>0,H24>0),G24/H24,"")
A25: 291 | B25: 2 | C25: antelope | D25: 2009 | E25: Draw | F25: 10 | G25: 63 | H25: 4 | I25: 4 | J25: 0 | K25: =IF(F25>0,H25/F25,"") | L25: =IF(AND(G25>0,H25>0),G25/H25,"")
A26: 291 | B26: 2 | C26: antelope | D26: 2010 | E26: Draw | F26: 7 | G26: 20 | H26: 3 | I26: 2 | J26: 2 | K26: =IF(F26>0,H26/F26,"") | L26: =IF(AND(G26>0,H26>0),G26/H26,"")
A27: 291 | B27: 2 | C27: antelope | D27: 2011 | E27: Draw | F27: 6 | G27: 19 | H27: 5 | I27: 2 | J27: 3 | K27: =IF(F27>0,H27/F27,"") | L27: =IF(AND(G27>0,H27>0),G27/H27,"")
A28: 291 | B28: 2 | C28: antelope | D28: 2012 | E28: Draw | F28: 9 | G28: 38 | H28: 2 | I28: 1 | J28: 1 | K28: =IF(F28>0,H28/F28,"") | L28: =IF(AND(G28>0,H28>0),G28/H28,"")
A29: 291 | B29: 2 | C29: antelope | D29: 2013 | E29: Draw | H29: 6 | I29: 3 | J29: 3 | K29: =IF(F29>0,H29/F29,"") | L29: =IF(AND(G29>0,H29>0),G29/H29,"")
A30: 291 | B30: 2 | C30: antelope | D30: 2014 | E30: Draw | F30: 13 | G30: 50 | H30: 9 | I30: 4 | J30: 5 | K30: =IF(F30>0,H30/F30,"") | L30: =IF(AND(G30>0,H30>0),G30/H30,"")
A31: 291 | B31: 2 | C31: antelope | D31: 2015 | E31: Draw | F31: 10 | G31: 26 | H31: 9 | I31: 4 | J31: 5 | K31: =IF(F31>0,H31/F31,"") | L31: =IF(AND(G31>0,H31>0),G31/H31,"")
A32: 291 | B32: 2 | C32: antelope | D32: 2016 | E32: Draw | H32: 5 | I32: 4 | J32: 1 | K32: =IF(F32>0,H32/F32,"") | L32: =IF(AND(G32>0,H32>0),G32/H32,"")
A33: 291 | B33: 2 | C33: antelope | D33: 2017 | E33: Draw | H33: 3 | I33: 1 | J33: 2 | K33: =IF(F33>0,H33/F33,"") | L33: =IF(AND(G33>0,H33>0),G33/H33,"")
A34: 291 | B34: 2 | C34: antelope | D34: 2018 | E34: Draw | F34: 23 | G34: 138 | H34: 5 | I34: 3 | J34: 3 | K34: =IF(F34>0,H34/F34,"") | L34: =IF(AND(G34>0,H34>0),G34/H34,"")
A35: 291 | B35: 2 | C35: antelope | D35: 2019 | E35: Draw | H35: 2 | I35: 0 | J35: 2 | K35: =IF(F35>0,H35/F35,"") | L35: =IF(AND(G35>0,H35>0),G35/H35,"")
A36: 291 | B36: 2 | C36: antelope | D36: 2020 | E36: Draw | F36: 19 | G36: 83 | H36: 3 | I36: 3 | J36: 0 | K36: =IF(F36>0,H36/F36,"") | L36: =IF(AND(G36>0,H36>0),G36/H36,"")
A37: 291 | B37: 2 | C37: antelope | D37: 2021 | E37: Draw | H37: 1 | I37: 1 | J37: 0 | K37: =IF(F37>0,H37/F37,"") | L37: =IF(AND(G37>0,H37>0),G37/H37,"")
A38: 291 | B38: 2 | C38: antelope | D38: 2022 | E38: Draw | F38: 16 | G38: 113 | H38: 9 | I38: 3 | J38: 6 | K38: =IF(F38>0,H38/F38,"") | L38: =IF(AND(G38>0,H38>0),G38/H38,"")
A39: 291 | B39: 2 | C39: antelope | D39: 2023 | E39: Draw | H39: 1 | I39: 1 | J39: 0 | K39: =IF(F39>0,H39/F39,"") | L39: =IF(AND(G39>0,H39>0),G39/H39,"")
A40: 291 | B40: 2 | C40: antelope | D40: 2024 | E40: Draw | F40: 2 | G40: 7 | H40: 1 | I40: 1 | J40: 0 | K40: =IF(F40>0,H40/F40,"") | L40: =IF(AND(G40>0,H40>0),G40/H40,"")
...
